Workbook
Name _xlchart.v1.0: P2_Product_Calcs!$A$5:$A$8
Name _xlchart.v1.1: P2_Product_Calcs!$B$5:$B$8

Sheet RawData
A1: Date | B1: Order_ID | C1: Customer_ID | D1: Category | E1: SKU | F1: Units | G1: Net_Revenue | H1: Region | I1: Channel | J1: Year | K1: Month | L1: Week | M1: MonthName | N1: MonthName
A2: 45835 | B2: ORD-10000 | C2: CUST-567 | D2: Capsules (Original) | E2: Arpeggio | F2: 150 | G2: 67.5 | H2: Lazio | I2: Mobile App | J2: 2025 | K2: 6 | L2: 26 | M2: Jun
A3: 45822 | B3: ORD-10001 | C3: CUST-887 | D3: Accessories | E3: Aeroccino 4 | F3: 1 | G3: 87.12 | H3: Sicilia | I3: Nespresso Boutique Pick-up | J3: 2025 | K3: 6 | L3: 24 | M3: Jun
A4: 45991 | B4: ORD-10002 | C4: CUST-851 | D4: Capsules (Vertuo) | E4: Melozio | F4: 150 | G4: 97.5 | H4: Sicilia | I4: Mobile App | J4: 2025 | K4: 11 | L4: 48 | M4: Nov
A5: 45793 | B5: ORD-10003 | C5: CUST-415 | D5: Capsules (Vertuo) | E5: Stormio | F5: 150 | G5: 97.5 | H5: Veneto | I5: Mobile App | J5: 2025 | K5: 5 | L5: 20 | M5: May
A6: 45787 | B6: ORD-10004 | C6: CUST-592 | D6: Capsules (Original) | E6: Livanto | F6: 150 | G6: 67.5 | H6: Piemonte | I6: Mobile App | J6: 2025 | K6: 5 | L6: 19 | M6: May
A7: 46062 | B7: ORD-10005 | C7: CUST-187 | D7: Accessories | E7: Nomad Travel Mug | F7: 1 | G7: 30.68 | H7: Toscana | I7: Desktop | J7: 2026 | K7: 2 | L7: 7 | M7: Feb
A8: 45961 | B8: ORD-10006 | C8: CUST-783 | D8: Capsules (Original) | E8: Arpeggio | F8: 30 | G8: 13.5 | H8: Sicilia | I8: Desktop | J8: 2025 | K8: 10 | L8: 44 | M8: Oct
A9: 45697 | B9: ORD-10007 | C9: CUST-925 | D9: Machines | E9: Essenza Mini | F9: 1 | G9: 499 | H9: Toscana | I9: Mobile App | J9: 2025 | K9: 2 | L9: 6 | M9: Feb
A10: 45849 | B10: ORD-10008 | C10: CUST-586 | D10: Accessories | E10: Descaling Kit | F10: 2 | G10: 38.84 | H10: Piemonte | I10: Desktop | J10: 2025 | K10: 7 | L10: 28 | M10: Jul
A11: 45786 | B11: ORD-10009 | C11: CUST-705 | D11: Capsules (Vertuo) | E11: Melozio | F11: 100 | G11: 65 | H11: Sicilia | I11: Nespresso Boutique Pick-up | J11: 2025 | K11: 5 | L11: 19 | M11: May
A12: 45728 | B12: ORD-10010 | C12: CUST-425 | D12: Capsules (Original) | E12: Arpeggio | F12: 30 | G12: 13.5 | H12: Lombardia | I12: Desktop | J12: 2025 | K12: 3 | L12: 11 | M12: Mar
A13: 46028 | B13: ORD-10011 | C13: CUST-111 | D13: Machines | E13: Essenza Mini | F13: 1 | G13: 99 | H13: Lombardia | I13: Desktop | J13: 2026 | K13: 1 | L13: 2 | M13: Jan
... A501: 46018 | B501: ORD-10499 | C501: CUST-628 | D501: Accessories | E501: Nomad Travel Mug | F501: 2 | G501: 168.99 | H501: Toscana | I501: Desktop | J501: 2025 | K501: 12 | L501: 52 | M501: Dec
G503: 52213.6

Sheet P1_Revenue_Calcs
A1: 📊 PAGE 1 — REVENUE OVERVIEW | Calculation Tables
A3: TABLE 1 — Monthly Revenue (feeds Bar Chart)
A4: Month_Num | B4: Month_Name | C4: Year | D4: Date | E4: Total_Revenue (€) | F4: MoM_Rev_Prev (€) | G4: MoM_Growth_% | H4: Use For
A5: 1 | B5: Jan | C5: 2025 | D5: =DATE(C5,A5,1) -> 45658 | E5: =SUMPRODUCT((RawData!$K$2:$K$503=1)*(RawData!$J$2:$J$503=2025)*(RawData!$G$2:$G$503)) -> 3581.94 | F5: — | G5: — | H5: Bar Chart + Line Chart MoM
A6: 2 | B6: Feb | C6: 2025 | D6: =DATE(C6,A6,1) -> 45689 | E6: =SUMPRODUCT((RawData!$K$2:$K$503=2)*(RawData!$J$2:$J$503=2025)*(RawData!$G$2:$G$503)) -> 3065.65 | F6: =E5 -> 3581.94 | G6: =IFERROR((E6-E5)/E5,"") -> -0.14413698 | H6: Bar Chart + Line Chart MoM
A7: 3 | B7: Mar | C7: 2025 | D7: =DATE(C7,A7,1) -> 45717 | E7: =SUMPRODUCT((RawData!$K$2:$K$503=3)*(RawData!$J$2:$J$503=2025)*(RawData!$G$2:$G$503)) -> 5458.18 | F7: =E6 -> 3065.65 | G7: =IFERROR((E7-E6)/E6,"") -> 0.78043156 | H7: Bar Chart + Line Chart MoM
A8: 4 | B8: Apr | C8: 2025 | D8: =DATE(C8,A8,1) -> 45748 | E8: =SUMPRODUCT((RawData!$K$2:$K$503=4)*(RawData!$J$2:$J$503=2025)*(RawData!$G$2:$G$503)) -> 2657.85 | F8: =E7 -> 5458.18 | G8: =IFERROR((E8-E7)/E7,"") -> -0.51305197 | H8: Bar Chart + Line Chart MoM
A9: 5 | B9: May | C9: 2025 | D9: =DATE(C9,A9,1) -> 45778 | E9: =SUMPRODUCT((RawData!$K$2:$K$503=5)*(RawData!$J$2:$J$503=2025)*(RawData!$G$2:$G$503)) -> 3109.38 | F9: =E8 -> 2657.85 | G9: =IFERROR((E9-E8)/E8,"") -> 0.16988543 | H9: Bar Chart + Line Chart MoM
A10: 6 | B10: Jun | C10: 2025 | D10: =DATE(C10,A10,1) -> 45809 | E10: =SUMPRODUCT((RawData!$K$2:$K$503=6)*(RawData!$J$2:$J$503=2025)*(RawData!$G$2:$G$503)) -> 4945.61 | F10: =E9 -> 3109.38 | G10: =IFERROR((E10-E9)/E9,"") -> 0.59054538 | H10: Bar Chart + Line Chart MoM
A11: 7 | B11: Jul | C11: 2025 | D11: =DATE(C11,A11,1) -> 45839 | E11: =SUMPRODUCT((RawData!$K$2:$K$503=7)*(RawData!$J$2:$J$503=2025)*(RawData!$G$2:$G$503)) -> 4846.58 | F11: =E10 -> 4945.61 | G11: =IFERROR((E11-E10)/E10,"") -> -0.020023819 | H11: Bar Chart + Line Chart MoM
A12: 8 | B12: Aug | C12: 2025 | D12: =DATE(C12,A12,1) -> 45870 | E12: =SUMPRODUCT((RawData!$K$2:$K$503=8)*(RawData!$J$2:$J$503=2025)*(RawData!$G$2:$G$503)) -> 2979.15 | F12: =E11 -> 4846.58 | G12: =IFERROR((E12-E11)/E11,"") -> -0.38530882 | H12: Bar Chart + Line Chart MoM
A13: 9 | B13: Sep | C13: 2025 | D13: =DATE(C13,A13,1) -> 45901 | E13: =SUMPRODUCT((RawData!$K$2:$K$503=9)*(RawData!$J$2:$J$503=2025)*(RawData!$G$2:$G$503)) -> 3727.52 | F13: =E12 -> 2979.15 | G13: =IFERROR((E13-E12)/E12,"") -> 0.25120252 | H13: Bar Chart + Line Chart MoM
A14: 10 | B14: Oct | C14: 2025 | D14: =DATE(C14,A14,1) -> 45931 | E14: =SUMPRODUCT((RawData!$K$2:$K$503=10)*(RawData!$J$2:$J$503=2025)*(RawData!$G$2:$G$503)) -> 2884.76 | F14: =E13 -> 3727.52 | G14: =IFERROR((E14-E13)/E13,"") -> -0.22609134 | H14: Bar Chart + Line Chart MoM
A15: 11 | B15: Nov | C15: 2025 | D15: =DATE(C15,A15,1) -> 45962 | E15: =SUMPRODUCT((RawData!$K$2:$K$503=11)*(RawData!$J$2:$J$503=2025)*(RawData!$G$2:$G$503)) -> 3558.09 | F15: =E14 -> 2884.76 | G15: =IFERROR((E15-E14)/E14,"") -> 0.23340937 | H15: Bar Chart + Line Chart MoM
A16: 12 | B16: Dec | C16: 2025 | D16: =DATE(C16,A16,1) -> 45992 | E16: =SUMPRODUCT((RawData!$K$2:$K$503=12)*(RawData!$J$2:$J$503=2025)*(RawData!$G$2:$G$503)) -> 3215.27 | F16: =E15 -> 3558.09 | G16: =IFERROR((E16-E15)/E15,"") -> -0.096349446 | H16: Bar Chart + Line Chart MoM
A17: 1 | B17: Jan | C17: 2026 | D17: =DATE(C17,A17,1) -> 46023 | E17: =SUMPRODUCT((RawData!$K$2:$K$503=1)*(RawData!$J$2:$J$503=2026)*(RawData!$G$2:$G$503)) -> 4240.38 | F17: =E16 -> 3215.27 | G17: =IFERROR((E17-E16)/E16,"") -> 0.31882548 | H17: Bar Chart 2026
A18: 2 | B18: Feb | C18: 2026 | D18: =DATE(C18,A18,1) -> 46054 | E18: =SUMPRODUCT((RawData!$K$2:$K$503=2)*(RawData!$J$2:$J$503=2026)*(RawData!$G$2:$G$503)) -> 2499.4 | F18: =E17 -> 4240.38 | G18: =IFERROR((E18-E17)/E17,"") -> -0.41057169 | H18: Bar Chart 2026
A19: 3 | B19: Mar | C19: 2026 | D19: =DATE(C19,A19,1) -> 46082 | E19: =SUMPRODUCT((RawData!$K$2:$K$503=3)*(RawData!$J$2:$J$503=2026)*(RawData!$G$2:$G$503)) -> 1443.84 | F19: =E18 -> 2499.4 | G19: =IFERROR((E19-E18)/E18,"") -> -0.42232536 | H19: Bar Chart 2026
A21: TABLE 2 — Weekly Revenue (feeds WoW Line Chart)
A22: Week_Num | B22: Year | C22: Date | D22: Total_Revenue (€) | E22: WoW_Prev (€) | F22: WoW_Growth_% | G22: Use For
A23: 1 | B23: 2025 | C23: =DATE(A23,B23,1) -> 61972 | D23: =SUMPRODUCT((RawData!$L$2:$L$503=1)*(RawData!$J$2:$J$503=2025)*(RawData!$G$2:$G$503)) -> 600.61 | E23: — | F23: — | G23: WoW Line Chart
A24: 2 | B24: 2025 | C24: =DATE(A24,B24,1) -> 62337 | D24: =SUMPRODUCT((RawData!$L$2:$L$503=2)*(RawData!$J$2:$J$503=2025)*(RawData!$G$2:$G$503)) -> 1397.44 | E24: =D23 -> 600.61 | F24: =IFERROR((D24-D23)/D23,"") -> 1.3267012 | G24: WoW Line Chart
A25: 3 | B25: 2025 | C25: =DATE(A25,B25,1) -> 62702 | D25: =SUMPRODUCT((RawData!$L$2:$L$503=3)*(RawData!$J$2:$J$503=2025)*(RawData!$G$2:$G$503)) -> 441.83 | E25: =D24 -> 1397.44 | F25: =IFERROR((D25-D24)/D24,"") -> -0.683829 | G25: WoW Line Chart
A26: 4 | B26: 2025 | C26: =DATE(A26,B26,1) -> 63068 | D26: =SUMPRODUCT((RawData!$L$2:$L$503=4)*(RawData!$J$2:$J$503=2025)*(RawData!$G$2:$G$503)) -> 665.15 | E26: =D25 -> 441.83 | F26: =IFERROR((D26-D25)/D25,"") -> 0.50544327 | G26: WoW Line Chart
A27: 5 | B27: 2025 | C27: =DATE(A27,B27,1) -> 63433 | D27: =SUMPRODUCT((RawData!$L$2:$L$503=5)*(RawData!$J$2:$J$503=2025)*(RawData!$G$2:$G$503)) -> 667.62 | E27: =D26 -> 665.15 | F27: =IFERROR((D27-D26)/D26,"") -> 0.0037134481 | G27: WoW Line Chart
A28: 6 | B28: 2025 | C28: =DATE(A28,B28,1) -> 63798 | D28: =SUMPRODUCT((RawData!$L$2:$L$503=6)*(RawData!$J$2:$J$503=2025)*(RawData!$G$2:$G$503)) -> 1135.71 | E28: =D27 -> 667.62 | F28: =IFERROR((D28-D27)/D27,"") -> 0.70113238 | G28: WoW Line Chart
A29: 7 | B29: 2025 | C29: =DATE(A29,B29,1) -> 64163 | D29: =SUMPRODUCT((RawData!$L$2:$L$503=7)*(RawData!$J$2:$J$503=2025)*(RawData!$G$2:$G$503)) -> 1076.56 | E29: =D28 -> 1135.71 | F29: =IFERROR((D29-D28)/D28,"") -> -0.052081958 | G29: WoW Line Chart
A30: 8 | B30: 2025 | C30: =DATE(A30,B30,1) -> 64529 | D30: =SUMPRODUCT((RawData!$L$2:$L$503=8)*(RawData!$J$2:$J$503=2025)*(RawData!$G$2:$G$503)) -> 581.21 | E30: =D29 -> 1076.56 | F30: =IFERROR((D30-D29)/D29,"") -> -0.46012298 | G30: WoW Line Chart
A31: 9 | B31: 2025 | C31: =DATE(A31,B31,1) -> 64894 | D31: =SUMPRODUCT((RawData!$L$2:$L$503=9)*(RawData!$J$2:$J$503=2025)*(RawData!$G$2:$G$503)) -> 1184.67 | E31: =D30 -> 581.21 | F31: =IFERROR((D31-D30)/D30,"") -> 1.0382822 | G31: WoW Line Chart
A32: 10 | B32: 2025 | C32: =DATE(A32,B32,1) -> 65259 | D32: =SUMPRODUCT((RawData!$L$2:$L$503=10)*(RawData!$J$2:$J$503=2025)*(RawData!$G$2:$G$503)) -> 860.5 | E32: =D31 -> 1184.67 | F32: =IFERROR((D32-D31)/D31,"") -> -0.27363738 | G32: WoW Line Chart
A33: 11 | B33: 2025 | C33: =DATE(A33,B33,1) -> 65624 | D33: =SUMPRODUCT((RawData!$L$2:$L$503=11)*(RawData!$J$2:$J$503=2025)*(RawData!$G$2:$G$503)) -> 1046.39 | E33: =D32 -> 860.5 | F33: =IFERROR((D33-D32)/D32,"") -> 0.21602557 | G33: WoW Line Chart
A34: 12 | B34: 2025 | C34: =DATE(A34,B34,1) -> 65990 | D34: =SUMPRODUCT((RawData!$L$2:$L$503=12)*(RawData!$J$2:$J$503=2025)*(RawData!$G$2:$G$503)) -> 1602.16 | E34: =D33 -> 1046.39 | F34: =IFERROR((D34-D33)/D33,"") -> 0.53113084 | G34: WoW Line Chart
A35: 13 | B35: 2025 | C35: =DATE(A35,B35,1) -> 66355 | D35: =SUMPRODUCT((RawData!$L$2:$L$503=13)*(RawData!$J$2:$J$503=2025)*(RawData!$G$2:$G$503)) -> 875.68 | E35: =D34 -> 1602.16 | F35: =IFERROR((D35-D34)/D34,"") -> -0.45343786 | G35: WoW Line Chart
A36: 14 | B36: 2025 | C36: =DATE(A36,B36,1) -> 66720 | D36: =SUMPRODUCT((RawData!$L$2:$L$503=14)*(RawData!$J$2:$J$503=2025)*(RawData!$G$2:$G$503)) -> 551.96 | E36: =D35 -> 875.68 | F36: =IFERROR((D36-D35)/D35,"") -> -0.36967842 | G36: WoW Line Chart
A37: 15 | B37: 2025 | C37: =DATE(A37,B37,1) -> 67085 | D37: =SUMPRODUCT((RawData!$L$2:$L$503=15)*(RawData!$J$2:$J$503=2025)*(RawData!$G$2:$G$503)) -> 626.02 | E37: =D36 -> 551.96 | F37: =IFERROR((D37-D36)/D36,"") -> 0.13417639 | G37: WoW Line Chart
A38: 16 | B38: 2025 | C38: =DATE(A38,B38,1) -> 67451 | D38: =SUMPRODUCT((RawData!$L$2:$L$503=16)*(RawData!$J$2:$J$503=2025)*(RawData!$G$2:$G$503)) -> 487.14 | E38: =D37 -> 626.02 | F38: =IFERROR((D38-D37)/D37,"") -> -0.22184595 | G38: WoW Line Chart
A39: 17 | B39: 2025 | C39: =DATE(A39,B39,1) -> 67816 | D39: =SUMPRODUCT((RawData!$L$2:$L$503=17)*(RawData!$J$2:$J$503=2025)*(RawData!$G$2:$G$503)) -> 888.18 | E39: =D38 -> 487.14 | F39: =IFERROR((D39-D38)/D38,"") -> 0.8232541 | G39: WoW Line Chart
A40: 18 | B40: 2025 | C40: =DATE(A40,B40,1) -> 68181 | D40: =SUMPRODUCT((RawData!$L$2:$L$503=18)*(RawData!$J$2:$J$503=2025)*(RawData!$G$2:$G$503)) -> 580.8 | E40: =D39 -> 888.18 | F40: =IFERROR((D40-D39)/D39,"") -> -0.3460785 | G40: WoW Line Chart
A41: 19 | B41: 2025 | C41: =DATE(A41,B41,1) -> 68546 | D41: =SUMPRODUCT((RawData!$L$2:$L$503=19)*(RawData!$J$2:$J$503=2025)*(RawData!$G$2:$G$503)) -> 427.5 | E41: =D40 -> 580.8 | F41: =IFERROR((D41-D40)/D40,"") -> -0.26394628 | G41: WoW Line Chart
A42: 20 | B42: 2025 | C42: =DATE(A42,B42,1) -> 68912 | D42: =SUMPRODUCT((RawData!$L$2:$L$503=20)*(RawData!$J$2:$J$503=2025)*(RawData!$G$2:$G$503)) -> 1112.79 | E42: =D41 -> 427.5 | F42: =IFERROR((D42-D41)/D41,"") -> 1.6030175 | G42: WoW Line Chart
...

Sheet P2_Product_Calcs
A1: 📦 PAGE 2 — PRODUCT & CATEGORY PERFORMANCE | Calculation Tables
A3: TABLE 1 — Category Revenue Share (feeds Donut + Treemap)
A4: Category | B4: Total_Revenue (€) | C4: Total_Units | D4: Revenue_Share_% | E4: Avg_Rev_per_Unit (€) | F4: Use For
A5: Capsules (Original) | B5: =SUMIF(RawData!$D$2:$D$503,"Capsules (Original)",RawData!$G$2:$G$503) -> 4387.5 | C5: =SUMIF(RawData!$D$2:$D$503,"Capsules (Original)",RawData!$F$2:$F$503) -> 9750 | D5: =IFERROR(B5/SUM(B5:B8),"") -> 0.084029831 | E5: =IFERROR(B5/C5,"") -> 0.45 | F5: Donut Chart + Treemap
A6: Capsules (Vertuo) | B6: =SUMIF(RawData!$D$2:$D$503,"Capsules (Vertuo)",RawData!$G$2:$G$503) -> 6292 | C6: =SUMIF(RawData!$D$2:$D$503,"Capsules (Vertuo)",RawData!$F$2:$F$503) -> 9680 | D6: =IFERROR(B6/SUM(B5:B8),"") -> 0.120505 | E6: =IFERROR(B6/C6,"") -> 0.65 | F6: Donut Chart + Treemap
A7: Accessories | B7: =SUMIF(RawData!$D$2:$D$503,"Accessories",RawData!$G$2:$G$503) -> 11210.1 | C7: =SUMIF(RawData!$D$2:$D$503,"Accessories",RawData!$F$2:$F$503) -> 213 | D7: =IFERROR(B7/SUM(B5:B8),"") -> 0.21469694 | E7: =IFERROR(B7/C7,"") -> 52.629577 | F7: Donut Chart + Treemap
A8: Machines | B8: =SUMIF(RawData!$D$2:$D$503,"Machines",RawData!$G$2:$G$503) -> 30324 | C8: =SUMIF(RawData!$D$2:$D$503,"Machines",RawData!$F$2:$F$503) -> 126 | D8: =IFERROR(B8/SUM(B5:B8),"") -> 0.58076823 | E8: =IFERROR(B8/C8,"") -> 240.66667 | F8: Donut Chart + Treemap
A10: TABLE 2 — SKU Revenue & Units (feeds Horizontal Bars + Scatter Plot)
A11: SKU | B11: Category | C11: Total_Revenue (€) | D11: Total_Units | E11: Rev_per_Unit (€) | F11: Rev_Rank | G11: Flag (below avg)
A12: Essenza Mini | B12: Machines | C12: =SUMIF(RawData!$E$2:$E$503,"Essenza Mini",RawData!$G$2:$G$503) -> 10659 | D12: =SUMIF(RawData!$E$2:$E$503,"Essenza Mini",RawData!$F$2:$F$503) -> 41 | E12: =IFERROR(C12/D12,"") -> 259.97561 | F12: =RANK(C12,C3:C14,0) -> 1 | G12: =IF(E12<AVERAGE(E3:E14),"⚠️ FLAG","OK") -> OK
A13: Creatista Plus | B13: Machines | C13: =SUMIF(RawData!$E$2:$E$503,"Creatista Plus",RawData!$G$2:$G$503) -> 10006 | D13: =SUMIF(RawData!$E$2:$E$503,"Creatista Plus",RawData!$F$2:$F$503) -> 44 | E13: =IFERROR(C13/D13,"") -> 227.40909 | F13: =RANK(C13,C3:C14,0) -> 2 | G13: =IF(E13<AVERAGE(E3:E14),"⚠️ FLAG","OK") -> OK
A14: Vertuo Pop | B14: Machines | C14: =SUMIF(RawData!$E$2:$E$503,"Vertuo Pop",RawData!$G$2:$G$503) -> 9659 | D14: =SUMIF(RawData!$E$2:$E$503,"Vertuo Pop",RawData!$F$2:$F$503) -> 41 | E14: =IFERROR(C14/D14,"") -> 235.58537 | F14: =RANK(C14,C3:C14,0) -> 5 | G14: =IF(E14<AVERAGE(E3:E14),"⚠️ FLAG","OK") -> OK
A15: Nomad Travel Mug | B15: Accessories | C15: =SUMIF(RawData!$E$2:$E$503,"Nomad Travel Mug",RawData!$G$2:$G$503) -> 5116.56 | D15: =SUMIF(RawData!$E$2:$E$503,"Nomad Travel Mug",RawData!$F$2:$F$503) -> 95 | E15: =IFERROR(C15/D15,"") -> 53.858526 | F15: =RANK(C15,C8:C19,0) -> 4 | G15: =IF(E15<AVERAGE(E8:E19),"⚠️ FLAG","OK") -> ⚠️ FLAG
A16: Aeroccino 4 | B16: Accessories | C16: =SUMIF(RawData!$E$2:$E$503,"Aeroccino 4",RawData!$G$2:$G$503) -> 3769.84 | D16: =SUMIF(RawData!$E$2:$E$503,"Aeroccino 4",RawData!$F$2:$F$503) -> 68 | E16: =IFERROR(C16/D16,"") -> 55.438824 | F16: =RANK(C16,C10:C21,0) -> 5 | G16: =IF(E16<AVERAGE(E10:E21),"⚠️ FLAG","OK") -> ⚠️ FLAG
A17: Stormio | B17: Capsules (Vertuo) | C17: =SUMIF(RawData!$E$2:$E$503,"Stormio",RawData!$G$2:$G$503) -> 2353 | D17: =SUMIF(RawData!$E$2:$E$503,"Stormio",RawData!$F$2:$F$503) -> 3620 | E17: =IFERROR(C17/D17,"") -> 0.65 | F17: =RANK(C17,C12:C23,0) -> 6 | G17: =IF(E17<AVERAGE(E12:E23),"⚠️ FLAG","OK") -> ⚠️ FLAG
A18: Descaling Kit | B18: Accessories | C18: =SUMIF(RawData!$E$2:$E$503,"Descaling Kit",RawData!$G$2:$G$503) -> 2323.7 | D18: =SUMIF(RawData!$E$2:$E$503,"Descaling Kit",RawData!$F$2:$F$503) -> 50 | E18: =IFERROR(C18/D18,"") -> 46.474 | F18: =RANK(C18,C10:C21,0) -> 7 | G18: =IF(E18<AVERAGE(E10:E21),"⚠️ FLAG","OK") -> ⚠️ FLAG
A19: Odacio | B19: Capsules (Original) | C19: =SUMIF(RawData!$E$2:$E$503,"Odacio",RawData!$G$2:$G$503) -> 2047.5 | D19: =SUMIF(RawData!$E$2:$E$503,"Odacio",RawData!$F$2:$F$503) -> 3150 | E19: =IFERROR(C19/D19,"") -> 0.65 | F19: =RANK(C19,C16:C27,0) -> 4 | G19: =IF(E19<AVERAGE(E16:E27),"⚠️ FLAG","OK") -> ⚠️ FLAG
A20: Melozio | B20: Capsules (Vertuo) | C20: =SUMIF(RawData!$E$2:$E$503,"Melozio",RawData!$G$2:$G$503) -> 1891.5 | D20: =SUMIF(RawData!$E$2:$E$503,"Melozio",RawData!$F$2:$F$503) -> 2910 | E20: =IFERROR(C20/D20,"") -> 0.65 | F20: =RANK(C20,C16:C27,0) -> 5 | G20: =IF(E20<AVERAGE(E16:E27),"⚠️ FLAG","OK") -> ⚠️ FLAG
A21: Roma | B21: Capsules (Original) | C21: =SUMIF(RawData!$E$2:$E$503,"Roma",RawData!$G$2:$G$503) -> 1566 | D21: =SUMIF(RawData!$E$2:$E$503,"Roma",RawData!$F$2:$F$503) -> 3480 | E21: =IFERROR(C21/D21,"") -> 0.45 | F21: =RANK(C21,C19:C30,0) -> 3 | G21: =IF(E21<AVERAGE(E19:E30),"⚠️ FLAG","OK") -> ⚠️ FLAG
A22: Livanto | B22: Capsules (Original) | C22: =SUMIF(RawData!$E$2:$E$503,"Livanto",RawData!$G$2:$G$503) -> 1417.5 | D22: =SUMIF(RawData!$E$2:$E$503,"Livanto",RawData!$F$2:$F$503) -> 3150 | E22: =IFERROR(C22/D22,"") -> 0.45 | F22: =RANK(C22,C21:C32,0) -> 2 | G22: =IF(E22<AVERAGE(E21:E32),"⚠️ FLAG","OK") -> OK
A23: Arpeggio | B23: Capsules (Original) | C23: =SUMIF(RawData!$E$2:$E$503,"Arpeggio",RawData!$G$2:$G$503) -> 1404 | D23: =SUMIF(RawData!$E$2:$E$503,"Arpeggio",RawData!$F$2:$F$503) -> 3120 | E23: =IFERROR(C23/D23,"") -> 0.45 | F23: =RANK(C23,C23:C34,0) -> 1 | G23: =IF(E23<AVERAGE(E23:E34),"⚠️ FLAG","OK") -> OK
G25: 📌 TOP 10 BY REVENUE: Sort Table 2 by column C (Rev) DESC → select first 10 rows → Insert Horizontal Bar Chart 📌 SCATTER PLOT: X-axis = column D (Units), Y-axis = column C (Revenue), one series per SKU. Highlight ⚠️ FLAG points in orange.
A27: TABLE 3 — KPI Cards for Page 2
A28: KPI | B28: Formula | C28: Format | D28: Interpretation
A29: Category Revenue Share % (Capsules) | B29: =IFERROR(SUMIF(RawData!$D$2:$D$503,"Capsules (Original)",RawData!$G$2:$G$503)/SUM(RawData!$G$2:$G$503),"") -> 0.042014916 | C29: 0.0% | D29: % of total revenue from Original Capsules | K29: Category Revenue Share % (Capsules) | P29: Category Revenue Share % (Vertuo)
A30: Category Revenue Share % (Vertuo) | B30: =IFERROR(SUMIF(RawData!$D$2:$D$503,"Capsules (Vertuo)",RawData!$G$2:$G$503)/SUM(RawData!$G$2:$G$503),"") -> 0.060252501 | C30: 0.0% | D30: % of total revenue from Vertuo Capsules | K30: =B29 -> 0.042014916 | P30: =B30 -> 0.060252501
A31: Category Revenue Share % (Accessories) | B31: =IFERROR(SUMIF(RawData!$D$2:$D$503,"Accessories",RawData!$G$2:$G$503)/SUM(RawData!$G$2:$G$503),"") -> 0.10734847 | C31: 0.0% | D31: % of total revenue from Accessories
A32: Category Revenue Share % (Machines) | B32: =IFERROR(SUMIF(RawData!$D$2:$D$503,"Machines",RawData!$G$2:$G$503)/SUM(RawData!$G$2:$G$503),"") -> 0.29038411 | C32: 0.0% | D32: % of total revenue from Machines
A33: Underperformance Flag Count | B33: =COUNTIF(P2_Product_Calcs!G12:G23,"⚠️ FLAG") -> 7 | C33: 0 | D33: # of SKUs with below-average revenue per unit
A34: Total SKUs | B34: =COUNTA(P2_Product_Calcs!A12:A23) -> 12 | C34: 0 | D34: Total distinct SKUs in dataset | K34: Category Revenue Share % (Accessories) | P34: Category Revenue Share % (Machines)
K35: =B31 -> 0.10734847 | P35: =B32 -> 0.29038411
K39: Underperformance Flag Count | P39: Total SKUs
K40: =COUNTIF(G12:G23,"⚠️ FLAG") -> 7 | P40: =B34 -> 12

Sheet P3_Channel_Calcs
A1: 📡 PAGE 3 — CHANNEL ANALYTICS | Calculation Tables
A3: TABLE 1 — Monthly Revenue by Channel (feeds Stacked Area Chart)
A4: Month_Num | B4: Month_Name | C4: Year | D4: Mobile App (€) | E4: Boutique (€) | F4: Desktop (€) | G4: Total (€) | H4: Use For
A5: 1 | B5: Jan | C5: 2025 | D5: =SUMPRODUCT((RawData!$I$2:$I$503="Mobile App")*(RawData!$K$2:$K$503=1)*(RawData!$J$2:$J$503=2025)*(RawData!$G$2:$G$503)) -> 980.91 | E5: =SUMPRODUCT((RawData!$I$2:$I$503="Nespresso Boutique Pick-up")*(RawData!$K$2:$K$503=1)*(RawData!$J$2:$J$503=2025)*(RawData!$G$2:$G$503)) -> 672.39 | F5: =SUMPRODUCT((RawData!$I$2:$I$503="Desktop")*(RawData!$K$2:$K$503=1)*(RawData!$J$2:$J$503=2025)*(RawData!$G$2:$G$503)) -> 1928.64 | G5: =D5+E5+F5 -> 3581.94 | H5: Stacked Area Chart
A6: 2 | B6: Feb | C6: 2025 | D6: =SUMPRODUCT((RawData!$I$2:$I$503="Mobile App")*(RawData!$K$2:$K$503=2)*(RawData!$J$2:$J$503=2025)*(RawData!$G$2:$G$503)) -> 1470.7 | E6: =SUMPRODUCT((RawData!$I$2:$I$503="Nespresso Boutique Pick-up")*(RawData!$K$2:$K$503=2)*(RawData!$J$2:$J$503=2025)*(RawData!$G$2:$G$503)) -> 1150.32 | F6: =SUMPRODUCT((RawData!$I$2:$I$503="Desktop")*(RawData!$K$2:$K$503=2)*(RawData!$J$2:$J$503=2025)*(RawData!$G$2:$G$503)) -> 444.63 | G6: =D6+E6+F6 -> 3065.65 | H6: Stacked Area Chart
A7: 3 | B7: Mar | C7: 2025 | D7: =SUMPRODUCT((RawData!$I$2:$I$503="Mobile App")*(RawData!$K$2:$K$503=3)*(RawData!$J$2:$J$503=2025)*(RawData!$G$2:$G$503)) -> 2069.45 | E7: =SUMPRODUCT((RawData!$I$2:$I$503="Nespresso Boutique Pick-up")*(RawData!$K$2:$K$503=3)*(RawData!$J$2:$J$503=2025)*(RawData!$G$2:$G$503)) -> 2065.37 | F7: =SUMPRODUCT((RawData!$I$2:$I$503="Desktop")*(RawData!$K$2:$K$503=3)*(RawData!$J$2:$J$503=2025)*(RawData!$G$2:$G$503)) -> 1323.36 | G7: =D7+E7+F7 -> 5458.18 | H7: Stacked Area Chart
A8: 4 | B8: Apr | C8: 2025 | D8: =SUMPRODUCT((RawData!$I$2:$I$503="Mobile App")*(RawData!$K$2:$K$503=4)*(RawData!$J$2:$J$503=2025)*(RawData!$G$2:$G$503)) -> 1081.62 | E8: =SUMPRODUCT((RawData!$I$2:$I$503="Nespresso Boutique Pick-up")*(RawData!$K$2:$K$503=4)*(RawData!$J$2:$J$503=2025)*(RawData!$G$2:$G$503)) -> 1026.42 | F8: =SUMPRODUCT((RawData!$I$2:$I$503="Desktop")*(RawData!$K$2:$K$503=4)*(RawData!$J$2:$J$503=2025)*(RawData!$G$2:$G$503)) -> 549.81 | G8: =D8+E8+F8 -> 2657.85 | H8: Stacked Area Chart
A9: 5 | B9: May | C9: 2025 | D9: =SUMPRODUCT((RawData!$I$2:$I$503="Mobile App")*(RawData!$K$2:$K$503=5)*(RawData!$J$2:$J$503=2025)*(RawData!$G$2:$G$503)) -> 1342.69 | E9: =SUMPRODUCT((RawData!$I$2:$I$503="Nespresso Boutique Pick-up")*(RawData!$K$2:$K$503=5)*(RawData!$J$2:$J$503=2025)*(RawData!$G$2:$G$503)) -> 344.28 | F9: =SUMPRODUCT((RawData!$I$2:$I$503="Desktop")*(RawData!$K$2:$K$503=5)*(RawData!$J$2:$J$503=2025)*(RawData!$G$2:$G$503)) -> 1422.41 | G9: =D9+E9+F9 -> 3109.38 | H9: Stacked Area Chart
A10: 6 | B10: Jun | C10: 2025 | D10: =SUMPRODUCT((RawData!$I$2:$I$503="Mobile App")*(RawData!$K$2:$K$503=6)*(RawData!$J$2:$J$503=2025)*(RawData!$G$2:$G$503)) -> 2002.5 | E10: =SUMPRODUCT((RawData!$I$2:$I$503="Nespresso Boutique Pick-up")*(RawData!$K$2:$K$503=6)*(RawData!$J$2:$J$503=2025)*(RawData!$G$2:$G$503)) -> 1793.12 | F10: =SUMPRODUCT((RawData!$I$2:$I$503="Desktop")*(RawData!$K$2:$K$503=6)*(RawData!$J$2:$J$503=2025)*(RawData!$G$2:$G$503)) -> 1149.99 | G10: =D10+E10+F10 -> 4945.61 | H10: Stacked Area Chart
A11: 7 | B11: Jul | C11: 2025 | D11: =SUMPRODUCT((RawData!$I$2:$I$503="Mobile App")*(RawData!$K$2:$K$503=7)*(RawData!$J$2:$J$503=2025)*(RawData!$G$2:$G$503)) -> 1662.18 | E11: =SUMPRODUCT((RawData!$I$2:$I$503="Nespresso Boutique Pick-up")*(RawData!$K$2:$K$503=7)*(RawData!$J$2:$J$503=2025)*(RawData!$G$2:$G$503)) -> 1832.9 | F11: =SUMPRODUCT((RawData!$I$2:$I$503="Desktop")*(RawData!$K$2:$K$503=7)*(RawData!$J$2:$J$503=2025)*(RawData!$G$2:$G$503)) -> 1351.5 | G11: =D11+E11+F11 -> 4846.58 | H11: Stacked Area Chart
A12: 8 | B12: Aug | C12: 2025 | D12: =SUMPRODUCT((RawData!$I$2:$I$503="Mobile App")*(RawData!$K$2:$K$503=8)*(RawData!$J$2:$J$503=2025)*(RawData!$G$2:$G$503)) -> 1753.69 | E12: =SUMPRODUCT((RawData!$I$2:$I$503="Nespresso Boutique Pick-up")*(RawData!$K$2:$K$503=8)*(RawData!$J$2:$J$503=2025)*(RawData!$G$2:$G$503)) -> 642.72 | F12: =SUMPRODUCT((RawData!$I$2:$I$503="Desktop")*(RawData!$K$2:$K$503=8)*(RawData!$J$2:$J$503=2025)*(RawData!$G$2:$G$503)) -> 582.74 | G12: =D12+E12+F12 -> 2979.15 | H12: Stacked Area Chart
A13: 9 | B13: Sep | C13: 2025 | D13: =SUMPRODUCT((RawData!$I$2:$I$503="Mobile App")*(RawData!$K$2:$K$503=9)*(RawData!$J$2:$J$503=2025)*(RawData!$G$2:$G$503)) -> 356.91 | E13: =SUMPRODUCT((RawData!$I$2:$I$503="Nespresso Boutique Pick-up")*(RawData!$K$2:$K$503=9)*(RawData!$J$2:$J$503=2025)*(RawData!$G$2:$G$503)) -> 2277.4 | F13: =SUMPRODUCT((RawData!$I$2:$I$503="Desktop")*(RawData!$K$2:$K$503=9)*(RawData!$J$2:$J$503=2025)*(RawData!$G$2:$G$503)) -> 1093.21 | G13: =D13+E13+F13 -> 3727.52 | H13: Stacked Area Chart
A14: 10 | B14: Oct | C14: 2025 | D14: =SUMPRODUCT((RawData!$I$2:$I$503="Mobile App")*(RawData!$K$2:$K$503=10)*(RawData!$J$2:$J$503=2025)*(RawData!$G$2:$G$503)) -> 1013.81 | E14: =SUMPRODUCT((RawData!$I$2:$I$503="Nespresso Boutique Pick-up")*(RawData!$K$2:$K$503=10)*(RawData!$J$2:$J$503=2025)*(RawData!$G$2:$G$503)) -> 681.4 | F14: =SUMPRODUCT((RawData!$I$2:$I$503="Desktop")*(RawData!$K$2:$K$503=10)*(RawData!$J$2:$J$503=2025)*(RawData!$G$2:$G$503)) -> 1189.55 | G14: =D14+E14+F14 -> 2884.76 | H14: Stacked Area Chart
A15: 11 | B15: Nov | C15: 2025 | D15: =SUMPRODUCT((RawData!$I$2:$I$503="Mobile App")*(RawData!$K$2:$K$503=11)*(RawData!$J$2:$J$503=2025)*(RawData!$G$2:$G$503)) -> 1645.69 | E15: =SUMPRODUCT((RawData!$I$2:$I$503="Nespresso Boutique Pick-up")*(RawData!$K$2:$K$503=11)*(RawData!$J$2:$J$503=2025)*(RawData!$G$2:$G$503)) -> 769.65 | F15: =SUMPRODUCT((RawData!$I$2:$I$503="Desktop")*(RawData!$K$2:$K$503=11)*(RawData!$J$2:$J$503=2025)*(RawData!$G$2:$G$503)) -> 1142.75 | G15: =D15+E15+F15 -> 3558.09 | H15: Stacked Area Chart
A16: 12 | B16: Dec | C16: 2025 | D16: =SUMPRODUCT((RawData!$I$2:$I$503="Mobile App")*(RawData!$K$2:$K$503=12)*(RawData!$J$2:$J$503=2025)*(RawData!$G$2:$G$503)) -> 249.05 | E16: =SUMPRODUCT((RawData!$I$2:$I$503="Nespresso Boutique Pick-up")*(RawData!$K$2:$K$503=12)*(RawData!$J$2:$J$503=2025)*(RawData!$G$2:$G$503)) -> 1485.46 | F16: =SUMPRODUCT((RawData!$I$2:$I$503="Desktop")*(RawData!$K$2:$K$503=12)*(RawData!$J$2:$J$503=2025)*(RawData!$G$2:$G$503)) -> 1480.76 | G16: =D16+E16+F16 -> 3215.27 | H16: Stacked Area Chart
A17: 1 | B17: Jan | C17: 2026 | D17: =SUMPRODUCT((RawData!$I$2:$I$503="Mobile App")*(RawData!$K$2:$K$503=1)*(RawData!$J$2:$J$503=2026)*(RawData!$G$2:$G$503)) -> 523.39 | E17: =SUMPRODUCT((RawData!$I$2:$I$503="Nespresso Boutique Pick-up")*(RawData!$K$2:$K$503=1)*(RawData!$J$2:$J$503=2026)*(RawData!$G$2:$G$503)) -> 1868.84 | F17: =SUMPRODUCT((RawData!$I$2:$I$503="Desktop")*(RawData!$K$2:$K$503=1)*(RawData!$J$2:$J$503=2026)*(RawData!$G$2:$G$503)) -> 1848.15 | G17: =D17+E17+F17 -> 4240.38 | H17: Stacked Area Chart
A18: 2 | B18: Feb | C18: 2026 | D18: =SUMPRODUCT((RawData!$I$2:$I$503="Mobile App")*(RawData!$K$2:$K$503=2)*(RawData!$J$2:$J$503=2026)*(RawData!$G$2:$G$503)) -> 408.77 | E18: =SUMPRODUCT((RawData!$I$2:$I$503="Nespresso Boutique Pick-up")*(RawData!$K$2:$K$503=2)*(RawData!$J$2:$J$503=2026)*(RawData!$G$2:$G$503)) -> 1062.26 | F18: =SUMPRODUCT((RawData!$I$2:$I$503="Desktop")*(RawData!$K$2:$K$503=2)*(RawData!$J$2:$J$503=2026)*(RawData!$G$2:$G$503)) -> 1028.37 | G18: =D18+E18+F18 -> 2499.4 | H18: Stacked Area Chart
A19: 3 | B19: Mar | C19: 2026 | D19: =SUMPRODUCT((RawData!$I$2:$I$503="Mobile App")*(RawData!$K$2:$K$503=3)*(RawData!$J$2:$J$503=2026)*(RawData!$G$2:$G$503)) -> 219.26 | E19: =SUMPRODUCT((RawData!$I$2:$I$503="Nespresso Boutique Pick-up")*(RawData!$K$2:$K$503=3)*(RawData!$J$2:$J$503=2026)*(RawData!$G$2:$G$503)) -> 234.88 | F19: =SUMPRODUCT((RawData!$I$2:$I$503="Desktop")*(RawData!$K$2:$K$503=3)*(RawData!$J$2:$J$503=2026)*(RawData!$G$2:$G$503)) -> 989.7 | G19: =D19+E19+F19 -> 1443.84 | H19: Stacked Area Chart
A21: TABLE 2 — MoM Growth % by Channel (feeds Multi-Series Line Chart)
A22: Month_Num | B22: Month_Name | C22: Year | D22: MobileApp_MoM% | E22: Boutique_MoM% | F22: Desktop_MoM% | G22: Total_MoM% | H22: Use For
A23: 1 | B23: Jan | C23: 2025 | D23: — | E23: — | F23: — | G23: — | H23: Multi-Series Line
A24: 2 | B24: Feb | C24: 2025 | D24: =IFERROR((D6-D5)/D5,"") -> 0.49932206 | E24: =IFERROR((E6-E5)/E5,"") -> 0.71079284 | F24: =IFERROR((F6-F5)/F5,"") -> -0.76945931 | G24: =IFERROR((G6-G5)/G5,"") -> -0.14413698 | H24: Multi-Series Line
A25: 3 | B25: Mar | C25: 2025 | D25: =IFERROR((D7-D6)/D6,"") -> 0.40711906 | E25: =IFERROR((E7-E6)/E6,"") -> 0.7954743 | F25: =IFERROR((F7-F6)/F6,"") -> 1.9763174 | G25: =IFERROR((G7-G6)/G6,"") -> 0.78043156 | H25: Multi-Series Line
A26: 4 | B26: Apr | C26: 2025 | D26: =IFERROR((D8-D7)/D7,"") -> -0.47733939 | E26: =IFERROR((E8-E7)/E7,"") -> -0.50303335 | F26: =IFERROR((F8-F7)/F7,"") -> -0.58453482 | G26: =IFERROR((G8-G7)/G7,"") -> -0.51305197 | H26: Multi-Series Line
A27: 5 | B27: May | C27: 2025 | D27: =IFERROR((D9-D8)/D8,"") -> 0.24136943 | E27: =IFERROR((E9-E8)/E8,"") -> -0.66458175 | F27: =IFERROR((F9-F8)/F8,"") -> 1.5870937 | G27: =IFERROR((G9-G8)/G8,"") -> 0.16988543 | H27: Multi-Series Line
A28: 6 | B28: Jun | C28: 2025 | D28: =IFERROR((D10-D9)/D9,"") -> 0.49140904 | E28: =IFERROR((E10-E9)/E9,"") -> 4.2083188 | F28: =IFERROR((F10-F9)/F9,"") -> -0.19152003 | G28: =IFERROR((G10-G9)/G9,"") -> 0.59054538 | H28: Multi-Series Line
A29: 7 | B29: Jul | C29: 2025 | D29: =IFERROR((D11-D10)/D10,"") -> -0.16994757 | E29: =IFERROR((E11-E10)/E10,"") -> 0.022184795 | F29: =IFERROR((F11-F10)/F10,"") -> 0.17522761 | G29: =IFERROR((G11-G10)/G10,"") -> -0.020023819 | H29: Multi-Series Line
A30: 8 | B30: Aug | C30: 2025 | D30: =IFERROR((D12-D11)/D11,"") -> 0.055054206 | E30: =IFERROR((E12-E11)/E11,"") -> -0.64934257 | F30: =IFERROR((F12-F11)/F11,"") -> -0.56881983 | G30: =IFERROR((G12-G11)/G11,"") -> -0.38530882 | H30: Multi-Series Line
A31: 9 | B31: Sep | C31: 2025 | D31: =IFERROR((D13-D12)/D12,"") -> -0.79648056 | E31: =IFERROR((E13-E12)/E12,"") -> 2.5433781 | F31: =IFERROR((F13-F12)/F12,"") -> 0.87598243 | G31: =IFERROR((G13-G12)/G12,"") -> 0.25120252 | H31: Multi-Series Line
A32: 10 | B32: Oct | C32: 2025 | D32: =IFERROR((D14-D13)/D13,"") -> 1.84052 | E32: =IFERROR((E14-E13)/E13,"") -> -0.70079916 | F32: =IFERROR((F14-F13)/F13,"") -> 0.088125795 | G32: =IFERROR((G14-G13)/G13,"") -> -0.22609134 | H32: Multi-Series Line
A33: 11 | B33: Nov | C33: 2025 | D33: =IFERROR((D15-D14)/D14,"") -> 0.62327261 | E33: =IFERROR((E15-E14)/E14,"") -> 0.12951277 | F33: =IFERROR((F15-F14)/F14,"") -> -0.039342609 | G33: =IFERROR((G15-G14)/G14,"") -> 0.23340937 | H33: Multi-Series Line
A34: 12 | B34: Dec | C34: 2025 | D34: =IFERROR((D16-D15)/D15,"") -> -0.8486653 | E34: =IFERROR((E16-E15)/E15,"") -> 0.93004612 | F34: =IFERROR((F16-F15)/F15,"") -> 0.29578648 | G34: =IFERROR((G16-G15)/G15,"") -> -0.096349446 | H34: Multi-Series Line
A35: 1 | B35: Jan | C35: 2026 | D35: =IFERROR((D17-D16)/D16,"") -> 1.1015459 | E35: =IFERROR((E17-E16)/E16,"") -> 0.2580884 | F35: =IFERROR((F17-F16)/F16,"") -> 0.24810908 | G35: =IFERROR((G17-G16)/G16,"") -> 0.31882548 | H35: Multi-Series Line
... A37: 3 | B37: Mar | C37: 2026 | D37: =IFERROR((D19-D18)/D18,"") -> -0.46361034 | E37: =IFERROR((E19-E18)/E18,"") -> -0.77888652 | F37: =IFERROR((F19-F18)/F18,"") -> -0.037603197 | G37: =IFERROR((G19-G18)/G18,"") -> -0.42232536 | H37: Multi-Series Line
A39: TABLE 3 — AOV by Channel (feeds Bar Chart)
A40: Channel | B40: Total_Revenue (€) | C40: Total_Orders | D40: AOV (€) | E40: Channel_Mix_% | F40: Use For
A41: Mobile App | B41: =SUMIF(RawData!$I$2:$I$503,"Mobile App",RawData!$G$2:$G$503) -> 16780.62 | C41: =COUNTIF(RawData!$I$2:$I$503,"Mobile App") -> 171 | D41: =IFERROR(B41/C41,"") -> 98.132281 | E41: =IFERROR(B41/SUM(B41:B43),"") -> 0.32138408 | F41: Bar Chart AOV
A42: Nespresso Boutique Pick-up | B42: =SUMIF(RawData!$I$2:$I$503,"Nespresso Boutique Pick-up",RawData!$G$2:$G$503) -> 17907.41 | C42: =COUNTIF(RawData!$I$2:$I$503,"Nespresso Boutique Pick-up") -> 154 | D42: =IFERROR(B42/C42,"") -> 116.28188 | E42: =IFERROR(B42/SUM(B41:B43),"") -> 0.34296448 | F42: Bar Chart AOV
A43: Desktop | B43: =SUMIF(RawData!$I$2:$I$503,"Desktop",RawData!$G$2:$G$503) -> 17525.57 | C43: =COUNTIF(RawData!$I$2:$I$503,"Desktop") -> 175 | D43: =IFERROR(B43/C43,"") -> 100.14611 | E43: =IFERROR(B43/SUM(B41:B43),"") -> 0.33565144 | F43: Bar Chart AOV
A45: TABLE 4 — KPI Cards for Page 3
...

Sheet P4_Customer_Calcs
A1: 👥 PAGE 4 — CUSTOMER SEGMENTATION | Calculation Tables
A3: TABLE 1 — Customer Order Frequency (feeds Donut + Histogram + Pareto)
G4: ⚙️ HOW TO BUILD: This table is a helper. In column A paste all unique Customer_IDs from RawData. Column B counts their total orders. Column C counts distinct months. Column D tags New vs Returning.
A5: Customer_ID | B5: Total_Orders | C5: Type (New/Returning) | D5: Total_Revenue (€) | E5: Pareto_Rank
A6: CUST-567 | B6: =COUNTIF(RawData!$C$2:$C$503,"CUST-567") -> 1 | C6: =IF(B6>1,"Returning","New") -> New | D6: =SUMIF(RawData!$C$2:$C$503,"CUST-567",RawData!$G$2:$G$503) -> 67.5 | E6: =RANK(D6,D6:D35,0) -> 19
A7: CUST-887 | B7: =COUNTIF(RawData!$C$2:$C$503,"CUST-887") -> 3 | C7: =IF(B7>1,"Returning","New") -> Returning | D7: =SUMIF(RawData!$C$2:$C$503,"CUST-887",RawData!$G$2:$G$503) -> 285.12 | E7: =RANK(D7,D6:D35,0) -> 4 | G7: New % | H7: =COUNTIF(C6:C382,"New")/COUNTA(A6:A382) -> 0.31481481
A8: CUST-851 | B8: =COUNTIF(RawData!$C$2:$C$503,"CUST-851") -> 1 | C8: =IF(B8>1,"Returning","New") -> New | D8: =SUMIF(RawData!$C$2:$C$503,"CUST-851",RawData!$G$2:$G$503) -> 97.5 | E8: =RANK(D8,D6:D35,0) -> 15 | G8: Returning % | H8: =COUNTIF(C6:C382,"Returning")/COUNTA(A6:A382) -> 0.24074074
A9: CUST-415 | B9: =COUNTIF(RawData!$C$2:$C$503,"CUST-415") -> 2 | C9: =IF(B9>1,"Returning","New") -> Returning | D9: =SUMIF(RawData!$C$2:$C$503,"CUST-415",RawData!$G$2:$G$503) -> 111 | E9: =RANK(D9,D6:D35,0) -> 12
A10: CUST-592 | B10: =COUNTIF(RawData!$C$2:$C$503,"CUST-592") -> 1 | C10: =IF(B10>1,"Returning","New") -> New | D10: =SUMIF(RawData!$C$2:$C$503,"CUST-592",RawData!$G$2:$G$503) -> 67.5 | E10: =RANK(D10,D6:D35,0) -> 19
A11: CUST-187 | B11: =COUNTIF(RawData!$C$2:$C$503,"CUST-187") -> 1 | C11: =IF(B11>1,"Returning","New") -> New | D11: =SUMIF(RawData!$C$2:$C$503,"CUST-187",RawData!$G$2:$G$503) -> 30.68 | E11: =RANK(D11,D6:D35,0) -> 27
A12: CUST-783 | B12: =COUNTIF(RawData!$C$2:$C$503,"CUST-783") -> 1 | C12: =IF(B12>1,"Returning","New") -> New | D12: =SUMIF(RawData!$C$2:$C$503,"CUST-783",RawData!$G$2:$G$503) -> 13.5 | E12: =RANK(D12,D6:D35,0) -> 29
A13: CUST-925 | B13: =COUNTIF(RawData!$C$2:$C$503,"CUST-925") -> 2 | C13: =IF(B13>1,"Returning","New") -> Returning | D13: =SUMIF(RawData!$C$2:$C$503,"CUST-925",RawData!$G$2:$G$503) -> 512.5 | E13: =RANK(D13,D6:D35,0) -> 2
A14: CUST-586 | B14: =COUNTIF(RawData!$C$2:$C$503,"CUST-586") -> 2 | C14: =IF(B14>1,"Returning","New") -> Returning | D14: =SUMIF(RawData!$C$2:$C$503,"CUST-586",RawData!$G$2:$G$503) -> 71.34 | E14: =RANK(D14,D6:D35,0) -> 18
A15: CUST-705 | B15: =COUNTIF(RawData!$C$2:$C$503,"CUST-705") -> 2 | C15: =IF(B15>1,"Returning","New") -> Returning | D15: =SUMIF(RawData!$C$2:$C$503,"CUST-705",RawData!$G$2:$G$503) -> 132.5 | E15: =RANK(D15,D6:D35,0) -> 9 | G15: New % | H15: =SUMIF(C6:C35,"New",D6:D35) -> 1483.41
A16: CUST-425 | B16: =COUNTIF(RawData!$C$2:$C$503,"CUST-425") -> 1 | C16: =IF(B16>1,"Returning","New") -> New | D16: =SUMIF(RawData!$C$2:$C$503,"CUST-425",RawData!$G$2:$G$503) -> 13.5 | E16: =RANK(D16,D6:D35,0) -> 29 | G16: Returning % | H16: =SUMIF(C7:C36,"Returning",D7:D36) -> 2748.09
A17: CUST-111 | B17: =COUNTIF(RawData!$C$2:$C$503,"CUST-111") -> 1 | C17: =IF(B17>1,"Returning","New") -> New | D17: =SUMIF(RawData!$C$2:$C$503,"CUST-111",RawData!$G$2:$G$503) -> 99 | E17: =RANK(D17,D6:D35,0) -> 13
A18: CUST-733 | B18: =COUNTIF(RawData!$C$2:$C$503,"CUST-733") -> 1 | C18: =IF(B18>1,"Returning","New") -> New | D18: =SUMIF(RawData!$C$2:$C$503,"CUST-733",RawData!$G$2:$G$503) -> 65 | E18: =RANK(D18,D6:D35,0) -> 21
A19: CUST-716 | B19: =COUNTIF(RawData!$C$2:$C$503,"CUST-716") -> 1 | C19: =IF(B19>1,"Returning","New") -> New | D19: =SUMIF(RawData!$C$2:$C$503,"CUST-716",RawData!$G$2:$G$503) -> 499 | E19: =RANK(D19,D6:D35,0) -> 3
A20: CUST-210 | B20: =COUNTIF(RawData!$C$2:$C$503,"CUST-210") -> 2 | C20: =IF(B20>1,"Returning","New") -> Returning | D20: =SUMIF(RawData!$C$2:$C$503,"CUST-210",RawData!$G$2:$G$503) -> 126.16 | E20: =RANK(D20,D6:D35,0) -> 11
A21: CUST-984 | B21: =COUNTIF(RawData!$C$2:$C$503,"CUST-984") -> 1 | C21: =IF(B21>1,"Returning","New") -> New | D21: =SUMIF(RawData!$C$2:$C$503,"CUST-984",RawData!$G$2:$G$503) -> 19.5 | E21: =RANK(D21,D6:D35,0) -> 28
A22: CUST-215 | B22: =COUNTIF(RawData!$C$2:$C$503,"CUST-215") -> 1 | C22: =IF(B22>1,"Returning","New") -> New | D22: =SUMIF(RawData!$C$2:$C$503,"CUST-215",RawData!$G$2:$G$503) -> 45.22 | E22: =RANK(D22,D6:D35,0) -> 24
A23: CUST-539 | B23: =COUNTIF(RawData!$C$2:$C$503,"CUST-539") -> 1 | C23: =IF(B23>1,"Returning","New") -> New | D23: =SUMIF(RawData!$C$2:$C$503,"CUST-539",RawData!$G$2:$G$503) -> 78.37 | E23: =RANK(D23,D6:D35,0) -> 17
A24: CUST-442 | B24: =COUNTIF(RawData!$C$2:$C$503,"CUST-442") -> 3 | C24: =IF(B24>1,"Returning","New") -> Returning | D24: =SUMIF(RawData!$C$2:$C$503,"CUST-442",RawData!$G$2:$G$503) -> 126.58 | E24: =RANK(D24,D6:D35,0) -> 10
A25: CUST-421 | B25: =COUNTIF(RawData!$C$2:$C$503,"CUST-421") -> 1 | C25: =IF(B25>1,"Returning","New") -> New | D25: =SUMIF(RawData!$C$2:$C$503,"CUST-421",RawData!$G$2:$G$503) -> 45 | E25: =RANK(D25,D6:D35,0) -> 25
A26: CUST-958 | B26: =COUNTIF(RawData!$C$2:$C$503,"CUST-958") -> 1 | C26: =IF(B26>1,"Returning","New") -> New | D26: =SUMIF(RawData!$C$2:$C$503,"CUST-958",RawData!$G$2:$G$503) -> 32.5 | E26: =RANK(D26,D6:D35,0) -> 26
A27: CUST-889 | B27: =COUNTIF(RawData!$C$2:$C$503,"CUST-889") -> 1 | C27: =IF(B27>1,"Returning","New") -> New | D27: =SUMIF(RawData!$C$2:$C$503,"CUST-889",RawData!$G$2:$G$503) -> 99 | E27: =RANK(D27,D6:D35,0) -> 13
A28: CUST-573 | B28: =COUNTIF(RawData!$C$2:$C$503,"CUST-573") -> 3 | C28: =IF(B28>1,"Returning","New") -> Returning | D28: =SUMIF(RawData!$C$2:$C$503,"CUST-573",RawData!$G$2:$G$503) -> 611.5 | E28: =RANK(D28,D6:D35,0) -> 1
A29: CUST-361 | B29: =COUNTIF(RawData!$C$2:$C$503,"CUST-361") -> 2 | C29: =IF(B29>1,"Returning","New") -> Returning | D29: =SUMIF(RawData!$C$2:$C$503,"CUST-361",RawData!$G$2:$G$503) -> 227.21 | E29: =RANK(D29,D6:D35,0) -> 6
A30: CUST-701 | B30: =COUNTIF(RawData!$C$2:$C$503,"CUST-701") -> 2 | C30: =IF(B30>1,"Returning","New") -> Returning | D30: =SUMIF(RawData!$C$2:$C$503,"CUST-701",RawData!$G$2:$G$503) -> 55 | E30: =RANK(D30,D6:D35,0) -> 23
A31: CUST-150 | B31: =COUNTIF(RawData!$C$2:$C$503,"CUST-150") -> 1 | C31: =IF(B31>1,"Returning","New") -> New | D31: =SUMIF(RawData!$C$2:$C$503,"CUST-150",RawData!$G$2:$G$503) -> 65 | E31: =RANK(D31,D6:D35,0) -> 21
A32: CUST-766 | B32: =COUNTIF(RawData!$C$2:$C$503,"CUST-766") -> 2 | C32: =IF(B32>1,"Returning","New") -> Returning | D32: =SUMIF(RawData!$C$2:$C$503,"CUST-766",RawData!$G$2:$G$503) -> 78.5 | E32: =RANK(D32,D6:D35,0) -> 16 | G32: ⚙️ METHOD: Tag each order in RawData as New/Returning using a helper column: =IF(COUNTIFS($C$2:C2,C2,$K$2:K2,"<"&K2)>0,"Returning","New") — then SUMIFS on that tag column per month.
A33: CUST-471 | B33: =COUNTIF(RawData!$C$2:$C$503,"CUST-471") -> 3 | C33: =IF(B33>1,"Returning","New") -> Returning | D33: =SUMIF(RawData!$C$2:$C$503,"CUST-471",RawData!$G$2:$G$503) -> 162.5 | E33: =RANK(D33,D6:D35,0) -> 7
A34: CUST-607 | B34: =COUNTIF(RawData!$C$2:$C$503,"CUST-607") -> 2 | C34: =IF(B34>1,"Returning","New") -> Returning | D34: =SUMIF(RawData!$C$2:$C$503,"CUST-607",RawData!$G$2:$G$503) -> 248.18 | E34: =RANK(D34,D6:D35,0) -> 5
A35: CUST-723 | B35: =COUNTIF(RawData!$C$2:$C$503,"CUST-723") -> 1 | C35: =IF(B35>1,"Returning","New") -> New | D35: =SUMIF(RawData!$C$2:$C$503,"CUST-723",RawData!$G$2:$G$503) -> 145.64 | E35: =RANK(D35,D6:D35,0) -> 8
G36: ⚠️ NOTE: This sample shows first 30 customers. For full dataset: copy-paste all 377 unique Customer_IDs from RawData!C column (deduplicated) into column A of this sheet, then drag formulas down.
A38: TABLE 2 — New vs Returning Revenue by Month (feeds Stacked Column + Line)
A39: Month_Num | B39: Month_Name | C39: Year | D39: Returning_Rev (€) | E39: New_Rev (€) | F39: Total_Rev (€) | G39: Returning_% | H39: Use For
A40: 1 | B40: Jan | C40: 2025 | D40: {=SUMPRODUCT((RawData!$J$2:$J$503=C40)*(RawData!$K$2:$K$503=A40)*(COUNTIFS(RawData!$C$2:$C$503,RawData!$C$2:$C$503,RawData!$A$2:$A$503,"<"&RawData!$A$2:$A$503)>0)*RawData!$G$2:$G$503)} -> 0 | E40: {=SUMPRODUCT((RawData!$J$2:$J$503=C40)*(RawData!$K$2:$K$503=A40)*(COUNTIFS(RawData!$C$2:$C$503,RawData!$C$2:$C$503,RawData!$A$2:$A$503,"<"&RawData!$A$2:$A$503)=0)*RawData!$G$2:$G$503)} -> 3581.94 | F40: =D40+E40 -> 3581.94 | G40: =IFERROR(D40/F40,0) -> 0 | H40: Stacked Column
A41: 2 | B41: Feb | C41: 2025 | D41: {=SUMPRODUCT((RawData!$J$2:$J$503=C41)*(RawData!$K$2:$K$503=A41)*(COUNTIFS(RawData!$C$2:$C$503,RawData!$C$2:$C$503,RawData!$A$2:$A$503,"<"&RawData!$A$2:$A$503)>0)*RawData!$G$2:$G$503)} -> 674.73 | E41: {=SUMPRODUCT((RawData!$J$2:$J$503=C41)*(RawData!$K$2:$K$503=A41)*(COUNTIFS(RawData!$C$2:$C$503,RawData!$C$2:$C$503,RawData!$A$2:$A$503,"<"&RawData!$A$2:$A$503)=0)*RawData!$G$2:$G$503)} -> 2390.92 | F41: =D41+E41 -> 3065.65 | G41: =IFERROR(D41/F41,0) -> 0.22009362 | H41: Stacked Column
A42: 3 | B42: Mar | C42: 2025 | D42: {=SUMPRODUCT((RawData!$J$2:$J$503=C42)*(RawData!$K$2:$K$503=A42)*(COUNTIFS(RawData!$C$2:$C$503,RawData!$C$2:$C$503,RawData!$A$2:$A$503,"<"&RawData!$A$2:$A$503)>0)*RawData!$G$2:$G$503)} -> 1544.19 | E42: {=SUMPRODUCT((RawData!$J$2:$J$503=C42)*(RawData!$K$2:$K$503=A42)*(COUNTIFS(RawData!$C$2:$C$503,RawData!$C$2:$C$503,RawData!$A$2:$A$503,"<"&RawData!$A$2:$A$503)=0)*RawData!$G$2:$G$503)} -> 3913.99 | F42: =D42+E42 -> 5458.18 | G42: =IFERROR(D42/F42,0) -> 0.28291299 | H42: Stacked Column
...

Sheet P5_Regional_Calcs
A1: 🗺️ PAGE 5 — REGIONAL PERFORMANCE | Calculation Tables
A3: TABLE 1 — Revenue & AOV by Region (feeds Grouped Bar Chart)
A4: Region | B4: Total_Revenue (€) | C4: Total_Orders | D4: AOV (€) | E4: Rev_Share_% | F4: Use For
A5: Lazio | B5: =SUMIF(RawData!$H$2:$H$503,"Lazio",RawData!$G$2:$G$503) -> 7028.65 | C5: =COUNTIF(RawData!$H$2:$H$503,"Lazio") -> 73 | D5: =IFERROR(B5/C5,"") -> 96.282877 | E5: =IFERROR(B5/SUM(B5:B11),"") -> 0.1346134 | F5: Grouped Bar Chart
A6: Sicilia | B6: =SUMIF(RawData!$H$2:$H$503,"Sicilia",RawData!$G$2:$G$503) -> 10478.61 | C6: =COUNTIF(RawData!$H$2:$H$503,"Sicilia") -> 88 | D6: =IFERROR(B6/C6,"") -> 119.07511 | E6: =IFERROR(B6/SUM(B5:B11),"") -> 0.20068737 | F6: Grouped Bar Chart
A7: Veneto | B7: =SUMIF(RawData!$H$2:$H$503,"Veneto",RawData!$G$2:$G$503) -> 5831.44 | C7: =COUNTIF(RawData!$H$2:$H$503,"Veneto") -> 62 | D7: =IFERROR(B7/C7,"") -> 94.055484 | E7: =IFERROR(B7/SUM(B5:B11),"") -> 0.11168431 | F7: Grouped Bar Chart
A8: Piemonte | B8: =SUMIF(RawData!$H$2:$H$503,"Piemonte",RawData!$G$2:$G$503) -> 7658.59 | C8: =COUNTIF(RawData!$H$2:$H$503,"Piemonte") -> 78 | D8: =IFERROR(B8/C8,"") -> 98.187051 | E8: =IFERROR(B8/SUM(B5:B11),"") -> 0.14667807 | F8: Grouped Bar Chart
A9: Toscana | B9: =SUMIF(RawData!$H$2:$H$503,"Toscana",RawData!$G$2:$G$503) -> 9106.14 | C9: =COUNTIF(RawData!$H$2:$H$503,"Toscana") -> 77 | D9: =IFERROR(B9/C9,"") -> 118.26156 | E9: =IFERROR(B9/SUM(B5:B11),"") -> 0.17440169 | F9: Grouped Bar Chart
A10: Lombardia | B10: =SUMIF(RawData!$H$2:$H$503,"Lombardia",RawData!$G$2:$G$503) -> 7234.61 | C10: =COUNTIF(RawData!$H$2:$H$503,"Lombardia") -> 66 | D10: =IFERROR(B10/C10,"") -> 109.6153 | E10: =IFERROR(B10/SUM(B5:B11),"") -> 0.13855796 | F10: Grouped Bar Chart
A11: Campania | B11: =SUMIF(RawData!$H$2:$H$503,"Campania",RawData!$G$2:$G$503) -> 4875.56 | C11: =COUNTIF(RawData!$H$2:$H$503,"Campania") -> 56 | D11: =IFERROR(B11/C11,"") -> 87.063571 | E11: =IFERROR(B11/SUM(B5:B11),"") -> 0.093377204 | F11: Grouped Bar Chart
A13: TABLE 2 — Monthly Revenue by Region (feeds Small Multiples Line + MoM)
A14: Month_Num | B14: Month_Name | C14: Year | D14: Lazio | E14: Sicilia | F14: Veneto | G14: Piemonte | H14: Toscana | I14: Lombardia | J14: Campania | K14: Use For
A15: 1 | B15: Jan | C15: 2025 | D15: =SUMPRODUCT((RawData!$H$2:$H$503="Lazio")*(RawData!$K$2:$K$503=1)*(RawData!$J$2:$J$503=2025)*(RawData!$G$2:$G$503)) -> 457.57 | E15: =SUMPRODUCT((RawData!$H$2:$H$503="Sicilia")*(RawData!$K$2:$K$503=1)*(RawData!$J$2:$J$503=2025)*(RawData!$G$2:$G$503)) -> 185.18 | F15: =SUMPRODUCT((RawData!$H$2:$H$503="Veneto")*(RawData!$K$2:$K$503=1)*(RawData!$J$2:$J$503=2025)*(RawData!$G$2:$G$503)) -> 305.28 | G15: =SUMPRODUCT((RawData!$H$2:$H$503="Piemonte")*(RawData!$K$2:$K$503=1)*(RawData!$J$2:$J$503=2025)*(RawData!$G$2:$G$503)) -> 897.27 | H15: =SUMPRODUCT((RawData!$H$2:$H$503="Toscana")*(RawData!$K$2:$K$503=1)*(RawData!$J$2:$J$503=2025)*(RawData!$G$2:$G$503)) -> 941.86 | I15: =SUMPRODUCT((RawData!$H$2:$H$503="Lombardia")*(RawData!$K$2:$K$503=1)*(RawData!$J$2:$J$503=2025)*(RawData!$G$2:$G$503)) -> 399.47 | J15: =SUMPRODUCT((RawData!$H$2:$H$503="Campania")*(RawData!$K$2:$K$503=1)*(RawData!$J$2:$J$503=2025)*(RawData!$G$2:$G$503)) -> 395.31 | K15: Small Multiples Line
A16: 2 | B16: Feb | C16: 2025 | D16: =SUMPRODUCT((RawData!$H$2:$H$503="Lazio")*(RawData!$K$2:$K$503=2)*(RawData!$J$2:$J$503=2025)*(RawData!$G$2:$G$503)) -> 293.39 | E16: =SUMPRODUCT((RawData!$H$2:$H$503="Sicilia")*(RawData!$K$2:$K$503=2)*(RawData!$J$2:$J$503=2025)*(RawData!$G$2:$G$503)) -> 791.51 | F16: =SUMPRODUCT((RawData!$H$2:$H$503="Veneto")*(RawData!$K$2:$K$503=2)*(RawData!$J$2:$J$503=2025)*(RawData!$G$2:$G$503)) -> 262.5 | G16: =SUMPRODUCT((RawData!$H$2:$H$503="Piemonte")*(RawData!$K$2:$K$503=2)*(RawData!$J$2:$J$503=2025)*(RawData!$G$2:$G$503)) -> 544.33 | H16: =SUMPRODUCT((RawData!$H$2:$H$503="Toscana")*(RawData!$K$2:$K$503=2)*(RawData!$J$2:$J$503=2025)*(RawData!$G$2:$G$503)) -> 713.81 | I16: =SUMPRODUCT((RawData!$H$2:$H$503="Lombardia")*(RawData!$K$2:$K$503=2)*(RawData!$J$2:$J$503=2025)*(RawData!$G$2:$G$503)) -> 348.3 | J16: =SUMPRODUCT((RawData!$H$2:$H$503="Campania")*(RawData!$K$2:$K$503=2)*(RawData!$J$2:$J$503=2025)*(RawData!$G$2:$G$503)) -> 111.81 | K16: Small Multiples Line
A17: 3 | B17: Mar | C17: 2025 | D17: =SUMPRODUCT((RawData!$H$2:$H$503="Lazio")*(RawData!$K$2:$K$503=3)*(RawData!$J$2:$J$503=2025)*(RawData!$G$2:$G$503)) -> 709.18 | E17: =SUMPRODUCT((RawData!$H$2:$H$503="Sicilia")*(RawData!$K$2:$K$503=3)*(RawData!$J$2:$J$503=2025)*(RawData!$G$2:$G$503)) -> 912.39 | F17: =SUMPRODUCT((RawData!$H$2:$H$503="Veneto")*(RawData!$K$2:$K$503=3)*(RawData!$J$2:$J$503=2025)*(RawData!$G$2:$G$503)) -> 521.5 | G17: =SUMPRODUCT((RawData!$H$2:$H$503="Piemonte")*(RawData!$K$2:$K$503=3)*(RawData!$J$2:$J$503=2025)*(RawData!$G$2:$G$503)) -> 796 | H17: =SUMPRODUCT((RawData!$H$2:$H$503="Toscana")*(RawData!$K$2:$K$503=3)*(RawData!$J$2:$J$503=2025)*(RawData!$G$2:$G$503)) -> 284.97 | I17: =SUMPRODUCT((RawData!$H$2:$H$503="Lombardia")*(RawData!$K$2:$K$503=3)*(RawData!$J$2:$J$503=2025)*(RawData!$G$2:$G$503)) -> 1386.14 | J17: =SUMPRODUCT((RawData!$H$2:$H$503="Campania")*(RawData!$K$2:$K$503=3)*(RawData!$J$2:$J$503=2025)*(RawData!$G$2:$G$503)) -> 848 | K17: Small Multiples Line
A18: 4 | B18: Apr | C18: 2025 | D18: =SUMPRODUCT((RawData!$H$2:$H$503="Lazio")*(RawData!$K$2:$K$503=4)*(RawData!$J$2:$J$503=2025)*(RawData!$G$2:$G$503)) -> 417.64 | E18: =SUMPRODUCT((RawData!$H$2:$H$503="Sicilia")*(RawData!$K$2:$K$503=4)*(RawData!$J$2:$J$503=2025)*(RawData!$G$2:$G$503)) -> 440.14 | F18: =SUMPRODUCT((RawData!$H$2:$H$503="Veneto")*(RawData!$K$2:$K$503=4)*(RawData!$J$2:$J$503=2025)*(RawData!$G$2:$G$503)) -> 531.5 | G18: =SUMPRODUCT((RawData!$H$2:$H$503="Piemonte")*(RawData!$K$2:$K$503=4)*(RawData!$J$2:$J$503=2025)*(RawData!$G$2:$G$503)) -> 487.62 | H18: =SUMPRODUCT((RawData!$H$2:$H$503="Toscana")*(RawData!$K$2:$K$503=4)*(RawData!$J$2:$J$503=2025)*(RawData!$G$2:$G$503)) -> 243.97 | I18: =SUMPRODUCT((RawData!$H$2:$H$503="Lombardia")*(RawData!$K$2:$K$503=4)*(RawData!$J$2:$J$503=2025)*(RawData!$G$2:$G$503)) -> 156 | J18: =SUMPRODUCT((RawData!$H$2:$H$503="Campania")*(RawData!$K$2:$K$503=4)*(RawData!$J$2:$J$503=2025)*(RawData!$G$2:$G$503)) -> 380.98 | K18: Small Multiples Line
A19: 5 | B19: May | C19: 2025 | D19: =SUMPRODUCT((RawData!$H$2:$H$503="Lazio")*(RawData!$K$2:$K$503=5)*(RawData!$J$2:$J$503=2025)*(RawData!$G$2:$G$503)) -> 441.79 | E19: =SUMPRODUCT((RawData!$H$2:$H$503="Sicilia")*(RawData!$K$2:$K$503=5)*(RawData!$J$2:$J$503=2025)*(RawData!$G$2:$G$503)) -> 862.75 | F19: =SUMPRODUCT((RawData!$H$2:$H$503="Veneto")*(RawData!$K$2:$K$503=5)*(RawData!$J$2:$J$503=2025)*(RawData!$G$2:$G$503)) -> 689.5 | G19: =SUMPRODUCT((RawData!$H$2:$H$503="Piemonte")*(RawData!$K$2:$K$503=5)*(RawData!$J$2:$J$503=2025)*(RawData!$G$2:$G$503)) -> 229.29 | H19: =SUMPRODUCT((RawData!$H$2:$H$503="Toscana")*(RawData!$K$2:$K$503=5)*(RawData!$J$2:$J$503=2025)*(RawData!$G$2:$G$503)) -> 109.76 | I19: =SUMPRODUCT((RawData!$H$2:$H$503="Lombardia")*(RawData!$K$2:$K$503=5)*(RawData!$J$2:$J$503=2025)*(RawData!$G$2:$G$503)) -> 672.08 | J19: =SUMPRODUCT((RawData!$H$2:$H$503="Campania")*(RawData!$K$2:$K$503=5)*(RawData!$J$2:$J$503=2025)*(RawData!$G$2:$G$503)) -> 104.21 | K19: Small Multiples Line
A20: 6 | B20: Jun | C20: 2025 | D20: =SUMPRODUCT((RawData!$H$2:$H$503="Lazio")*(RawData!$K$2:$K$503=6)*(RawData!$J$2:$J$503=2025)*(RawData!$G$2:$G$503)) -> 827.73 | E20: =SUMPRODUCT((RawData!$H$2:$H$503="Sicilia")*(RawData!$K$2:$K$503=6)*(RawData!$J$2:$J$503=2025)*(RawData!$G$2:$G$503)) -> 664.62 | F20: =SUMPRODUCT((RawData!$H$2:$H$503="Veneto")*(RawData!$K$2:$K$503=6)*(RawData!$J$2:$J$503=2025)*(RawData!$G$2:$G$503)) -> 0 | G20: =SUMPRODUCT((RawData!$H$2:$H$503="Piemonte")*(RawData!$K$2:$K$503=6)*(RawData!$J$2:$J$503=2025)*(RawData!$G$2:$G$503)) -> 1071.07 | H20: =SUMPRODUCT((RawData!$H$2:$H$503="Toscana")*(RawData!$K$2:$K$503=6)*(RawData!$J$2:$J$503=2025)*(RawData!$G$2:$G$503)) -> 750 | I20: =SUMPRODUCT((RawData!$H$2:$H$503="Lombardia")*(RawData!$K$2:$K$503=6)*(RawData!$J$2:$J$503=2025)*(RawData!$G$2:$G$503)) -> 1050.5 | J20: =SUMPRODUCT((RawData!$H$2:$H$503="Campania")*(RawData!$K$2:$K$503=6)*(RawData!$J$2:$J$503=2025)*(RawData!$G$2:$G$503)) -> 581.69 | K20: Small Multiples Line
A21: 7 | B21: Jul | C21: 2025 | D21: =SUMPRODUCT((RawData!$H$2:$H$503="Lazio")*(RawData!$K$2:$K$503=7)*(RawData!$J$2:$J$503=2025)*(RawData!$G$2:$G$503)) -> 1486.02 | E21: =SUMPRODUCT((RawData!$H$2:$H$503="Sicilia")*(RawData!$K$2:$K$503=7)*(RawData!$J$2:$J$503=2025)*(RawData!$G$2:$G$503)) -> 1613.17 | F21: =SUMPRODUCT((RawData!$H$2:$H$503="Veneto")*(RawData!$K$2:$K$503=7)*(RawData!$J$2:$J$503=2025)*(RawData!$G$2:$G$503)) -> 204 | G21: =SUMPRODUCT((RawData!$H$2:$H$503="Piemonte")*(RawData!$K$2:$K$503=7)*(RawData!$J$2:$J$503=2025)*(RawData!$G$2:$G$503)) -> 405.95 | H21: =SUMPRODUCT((RawData!$H$2:$H$503="Toscana")*(RawData!$K$2:$K$503=7)*(RawData!$J$2:$J$503=2025)*(RawData!$G$2:$G$503)) -> 747.94 | I21: =SUMPRODUCT((RawData!$H$2:$H$503="Lombardia")*(RawData!$K$2:$K$503=7)*(RawData!$J$2:$J$503=2025)*(RawData!$G$2:$G$503)) -> 333.5 | J21: =SUMPRODUCT((RawData!$H$2:$H$503="Campania")*(RawData!$K$2:$K$503=7)*(RawData!$J$2:$J$503=2025)*(RawData!$G$2:$G$503)) -> 56 | K21: Small Multiples Line
A22: 8 | B22: Aug | C22: 2025 | D22: =SUMPRODUCT((RawData!$H$2:$H$503="Lazio")*(RawData!$K$2:$K$503=8)*(RawData!$J$2:$J$503=2025)*(RawData!$G$2:$G$503)) -> 103.54 | E22: =SUMPRODUCT((RawData!$H$2:$H$503="Sicilia")*(RawData!$K$2:$K$503=8)*(RawData!$J$2:$J$503=2025)*(RawData!$G$2:$G$503)) -> 641.63 | F22: =SUMPRODUCT((RawData!$H$2:$H$503="Veneto")*(RawData!$K$2:$K$503=8)*(RawData!$J$2:$J$503=2025)*(RawData!$G$2:$G$503)) -> 265.5 | G22: =SUMPRODUCT((RawData!$H$2:$H$503="Piemonte")*(RawData!$K$2:$K$503=8)*(RawData!$J$2:$J$503=2025)*(RawData!$G$2:$G$503)) -> 779.04 | H22: =SUMPRODUCT((RawData!$H$2:$H$503="Toscana")*(RawData!$K$2:$K$503=8)*(RawData!$J$2:$J$503=2025)*(RawData!$G$2:$G$503)) -> 319.94 | I22: =SUMPRODUCT((RawData!$H$2:$H$503="Lombardia")*(RawData!$K$2:$K$503=8)*(RawData!$J$2:$J$503=2025)*(RawData!$G$2:$G$503)) -> 769.5 | J22: =SUMPRODUCT((RawData!$H$2:$H$503="Campania")*(RawData!$K$2:$K$503=8)*(RawData!$J$2:$J$503=2025)*(RawData!$G$2:$G$503)) -> 100 | K22: Small Multiples Line
A23: 9 | B23: Sep | C23: 2025 | D23: =SUMPRODUCT((RawData!$H$2:$H$503="Lazio")*(RawData!$K$2:$K$503=9)*(RawData!$J$2:$J$503=2025)*(RawData!$G$2:$G$503)) -> 605.63 | E23: =SUMPRODUCT((RawData!$H$2:$H$503="Sicilia")*(RawData!$K$2:$K$503=9)*(RawData!$J$2:$J$503=2025)*(RawData!$G$2:$G$503)) -> 494.14 | F23: =SUMPRODUCT((RawData!$H$2:$H$503="Veneto")*(RawData!$K$2:$K$503=9)*(RawData!$J$2:$J$503=2025)*(RawData!$G$2:$G$503)) -> 762.71 | G23: =SUMPRODUCT((RawData!$H$2:$H$503="Piemonte")*(RawData!$K$2:$K$503=9)*(RawData!$J$2:$J$503=2025)*(RawData!$G$2:$G$503)) -> 326.76 | H23: =SUMPRODUCT((RawData!$H$2:$H$503="Toscana")*(RawData!$K$2:$K$503=9)*(RawData!$J$2:$J$503=2025)*(RawData!$G$2:$G$503)) -> 1038.2 | I23: =SUMPRODUCT((RawData!$H$2:$H$503="Lombardia")*(RawData!$K$2:$K$503=9)*(RawData!$J$2:$J$503=2025)*(RawData!$G$2:$G$503)) -> 326.23 | J23: =SUMPRODUCT((RawData!$H$2:$H$503="Campania")*(RawData!$K$2:$K$503=9)*(RawData!$J$2:$J$503=2025)*(RawData!$G$2:$G$503)) -> 173.85 | K23: Small Multiples Line
A24: 10 | B24: Oct | C24: 2025 | D24: =SUMPRODUCT((RawData!$H$2:$H$503="Lazio")*(RawData!$K$2:$K$503=10)*(RawData!$J$2:$J$503=2025)*(RawData!$G$2:$G$503)) -> 566.5 | E24: =SUMPRODUCT((RawData!$H$2:$H$503="Sicilia")*(RawData!$K$2:$K$503=10)*(RawData!$J$2:$J$503=2025)*(RawData!$G$2:$G$503)) -> 505.92 | F24: =SUMPRODUCT((RawData!$H$2:$H$503="Veneto")*(RawData!$K$2:$K$503=10)*(RawData!$J$2:$J$503=2025)*(RawData!$G$2:$G$503)) -> 488.03 | G24: =SUMPRODUCT((RawData!$H$2:$H$503="Piemonte")*(RawData!$K$2:$K$503=10)*(RawData!$J$2:$J$503=2025)*(RawData!$G$2:$G$503)) -> 171.5 | H24: =SUMPRODUCT((RawData!$H$2:$H$503="Toscana")*(RawData!$K$2:$K$503=10)*(RawData!$J$2:$J$503=2025)*(RawData!$G$2:$G$503)) -> 440.27 | I24: =SUMPRODUCT((RawData!$H$2:$H$503="Lombardia")*(RawData!$K$2:$K$503=10)*(RawData!$J$2:$J$503=2025)*(RawData!$G$2:$G$503)) -> 380.51 | J24: =SUMPRODUCT((RawData!$H$2:$H$503="Campania")*(RawData!$K$2:$K$503=10)*(RawData!$J$2:$J$503=2025)*(RawData!$G$2:$G$503)) -> 332.03 | K24: Small Multiples Line
A25: 11 | B25: Nov | C25: 2025 | D25: =SUMPRODUCT((RawData!$H$2:$H$503="Lazio")*(RawData!$K$2:$K$503=11)*(RawData!$J$2:$J$503=2025)*(RawData!$G$2:$G$503)) -> 76.07 | E25: =SUMPRODUCT((RawData!$H$2:$H$503="Sicilia")*(RawData!$K$2:$K$503=11)*(RawData!$J$2:$J$503=2025)*(RawData!$G$2:$G$503)) -> 345.5 | F25: =SUMPRODUCT((RawData!$H$2:$H$503="Veneto")*(RawData!$K$2:$K$503=11)*(RawData!$J$2:$J$503=2025)*(RawData!$G$2:$G$503)) -> 647.73 | G25: =SUMPRODUCT((RawData!$H$2:$H$503="Piemonte")*(RawData!$K$2:$K$503=11)*(RawData!$J$2:$J$503=2025)*(RawData!$G$2:$G$503)) -> 737.02 | H25: =SUMPRODUCT((RawData!$H$2:$H$503="Toscana")*(RawData!$K$2:$K$503=11)*(RawData!$J$2:$J$503=2025)*(RawData!$G$2:$G$503)) -> 1187.45 | I25: =SUMPRODUCT((RawData!$H$2:$H$503="Lombardia")*(RawData!$K$2:$K$503=11)*(RawData!$J$2:$J$503=2025)*(RawData!$G$2:$G$503)) -> 329 | J25: =SUMPRODUCT((RawData!$H$2:$H$503="Campania")*(RawData!$K$2:$K$503=11)*(RawData!$J$2:$J$503=2025)*(RawData!$G$2:$G$503)) -> 235.32 | K25: Small Multiples Line
A26: 12 | B26: Dec | C26: 2025 | D26: =SUMPRODUCT((RawData!$H$2:$H$503="Lazio")*(RawData!$K$2:$K$503=12)*(RawData!$J$2:$J$503=2025)*(RawData!$G$2:$G$503)) -> 166 | E26: =SUMPRODUCT((RawData!$H$2:$H$503="Sicilia")*(RawData!$K$2:$K$503=12)*(RawData!$J$2:$J$503=2025)*(RawData!$G$2:$G$503)) -> 1182.78 | F26: =SUMPRODUCT((RawData!$H$2:$H$503="Veneto")*(RawData!$K$2:$K$503=12)*(RawData!$J$2:$J$503=2025)*(RawData!$G$2:$G$503)) -> 248.74 | G26: =SUMPRODUCT((RawData!$H$2:$H$503="Piemonte")*(RawData!$K$2:$K$503=12)*(RawData!$J$2:$J$503=2025)*(RawData!$G$2:$G$503)) -> 202.94 | H26: =SUMPRODUCT((RawData!$H$2:$H$503="Toscana")*(RawData!$K$2:$K$503=12)*(RawData!$J$2:$J$503=2025)*(RawData!$G$2:$G$503)) -> 714.54 | I26: =SUMPRODUCT((RawData!$H$2:$H$503="Lombardia")*(RawData!$K$2:$K$503=12)*(RawData!$J$2:$J$503=2025)*(RawData!$G$2:$G$503)) -> 117 | J26: =SUMPRODUCT((RawData!$H$2:$H$503="Campania")*(RawData!$K$2:$K$503=12)*(RawData!$J$2:$J$503=2025)*(RawData!$G$2:$G$503)) -> 583.27 | K26: Small Multiples Line
A27: 1 | B27: Jan | C27: 2026 | D27: =SUMPRODUCT((RawData!$H$2:$H$503="Lazio")*(RawData!$K$2:$K$503=1)*(RawData!$J$2:$J$503=2026)*(RawData!$G$2:$G$503)) -> 553 | E27: =SUMPRODUCT((RawData!$H$2:$H$503="Sicilia")*(RawData!$K$2:$K$503=1)*(RawData!$J$2:$J$503=2026)*(RawData!$G$2:$G$503)) -> 1186 | F27: =SUMPRODUCT((RawData!$H$2:$H$503="Veneto")*(RawData!$K$2:$K$503=1)*(RawData!$J$2:$J$503=2026)*(RawData!$G$2:$G$503)) -> 671.77 | G27: =SUMPRODUCT((RawData!$H$2:$H$503="Piemonte")*(RawData!$K$2:$K$503=1)*(RawData!$J$2:$J$503=2026)*(RawData!$G$2:$G$503)) -> 778.96 | H27: =SUMPRODUCT((RawData!$H$2:$H$503="Toscana")*(RawData!$K$2:$K$503=1)*(RawData!$J$2:$J$503=2026)*(RawData!$G$2:$G$503)) -> 580 | I27: =SUMPRODUCT((RawData!$H$2:$H$503="Lombardia")*(RawData!$K$2:$K$503=1)*(RawData!$J$2:$J$503=2026)*(RawData!$G$2:$G$503)) -> 118.5 | J27: =SUMPRODUCT((RawData!$H$2:$H$503="Campania")*(RawData!$K$2:$K$503=1)*(RawData!$J$2:$J$503=2026)*(RawData!$G$2:$G$503)) -> 352.15 | K27: Small Multiples Line
A28: 2 | B28: Feb | C28: 2026 | D28: =SUMPRODUCT((RawData!$H$2:$H$503="Lazio")*(RawData!$K$2:$K$503=2)*(RawData!$J$2:$J$503=2026)*(RawData!$G$2:$G$503)) -> 179.39 | E28: =SUMPRODUCT((RawData!$H$2:$H$503="Sicilia")*(RawData!$K$2:$K$503=2)*(RawData!$J$2:$J$503=2026)*(RawData!$G$2:$G$503)) -> 524.84 | F28: =SUMPRODUCT((RawData!$H$2:$H$503="Veneto")*(RawData!$K$2:$K$503=2)*(RawData!$J$2:$J$503=2026)*(RawData!$G$2:$G$503)) -> 232.68 | G28: =SUMPRODUCT((RawData!$H$2:$H$503="Piemonte")*(RawData!$K$2:$K$503=2)*(RawData!$J$2:$J$503=2026)*(RawData!$G$2:$G$503)) -> 133.34 | H28: =SUMPRODUCT((RawData!$H$2:$H$503="Toscana")*(RawData!$K$2:$K$503=2)*(RawData!$J$2:$J$503=2026)*(RawData!$G$2:$G$503)) -> 934.43 | I28: =SUMPRODUCT((RawData!$H$2:$H$503="Lombardia")*(RawData!$K$2:$K$503=2)*(RawData!$J$2:$J$503=2026)*(RawData!$G$2:$G$503)) -> 211.5 | J28: =SUMPRODUCT((RawData!$H$2:$H$503="Campania")*(RawData!$K$2:$K$503=2)*(RawData!$J$2:$J$503=2026)*(RawData!$G$2:$G$503)) -> 283.22 | K28: Small Multiples Line
A29: 3 | B29: Mar | C29: 2026 | D29: =SUMPRODUCT((RawData!$H$2:$H$503="Lazio")*(RawData!$K$2:$K$503=3)*(RawData!$J$2:$J$503=2026)*(RawData!$G$2:$G$503)) -> 145.2 | E29: =SUMPRODUCT((RawData!$H$2:$H$503="Sicilia")*(RawData!$K$2:$K$503=3)*(RawData!$J$2:$J$503=2026)*(RawData!$G$2:$G$503)) -> 128.04 | F29: =SUMPRODUCT((RawData!$H$2:$H$503="Veneto")*(RawData!$K$2:$K$503=3)*(RawData!$J$2:$J$503=2026)*(RawData!$G$2:$G$503)) -> 0 | G29: =SUMPRODUCT((RawData!$H$2:$H$503="Piemonte")*(RawData!$K$2:$K$503=3)*(RawData!$J$2:$J$503=2026)*(RawData!$G$2:$G$503)) -> 97.5 | H29: =SUMPRODUCT((RawData!$H$2:$H$503="Toscana")*(RawData!$K$2:$K$503=3)*(RawData!$J$2:$J$503=2026)*(RawData!$G$2:$G$503)) -> 99 | I29: =SUMPRODUCT((RawData!$H$2:$H$503="Lombardia")*(RawData!$K$2:$K$503=3)*(RawData!$J$2:$J$503=2026)*(RawData!$G$2:$G$503)) -> 636.38 | J29: =SUMPRODUCT((RawData!$H$2:$H$503="Campania")*(RawData!$K$2:$K$503=3)*(RawData!$J$2:$J$503=2026)*(RawData!$G$2:$G$503)) -> 337.72 | K29: Small Multiples Line
A31: TABLE 3 — MoM Growth % by Region (feeds Small Multiples Line — % view)
A32: Month_Num | B32: Month_Name | C32: Year | D32: Lazio_MoM% | E32: Sicilia_MoM% | F32: Veneto_MoM% | G32: Piemonte_MoM% | H32: Toscana_MoM% | I32: Lombardia_MoM% | J32: Campania_MoM% | K32: Use For
A33: 1 | B33: Jan | C33: 2025 | D33: — | E33: — | F33: — | G33: — | H33: — | I33: — | J33: — | K33: MoM Line Chart
A34: 2 | B34: Feb | C34: 2025 | D34: =IFERROR((D16-D15)/D15,"") -> -0.35880849 | E34: =IFERROR((E16-E15)/E15,"") -> 3.2742737 | F34: =IFERROR((F16-F15)/F15,"") -> -0.14013365 | G34: =IFERROR((G16-G15)/G15,"") -> -0.39334871 | H34: =IFERROR((H16-H15)/H15,"") -> -0.24212728 | I34: =IFERROR((I16-I15)/I15,"") -> -0.12809473 | J34: =IFERROR((J16-J15)/J15,"") -> -0.71715869 | K34: MoM Line Chart
A35: 3 | B35: Mar | C35: 2025 | D35: =IFERROR((D17-D16)/D16,"") -> 1.4171921 | E35: =IFERROR((E17-E16)/E16,"") -> 0.15272075 | F35: =IFERROR((F17-F16)/F16,"") -> 0.98666667 | G35: =IFERROR((G17-G16)/G16,"") -> 0.46234821 | H35: =IFERROR((H17-H16)/H16,"") -> -0.60077612 | I35: =IFERROR((I17-I16)/I16,"") -> 2.9797301 | J35: =IFERROR((J17-J16)/J16,"") -> 6.5842948 | K35: MoM Line Chart
